Workbook

Sheet Assumptions
A1: Assumptions — Pricing Grid, Factors, Probabilities
A3: Trial price default (HK$/hr)
A4: Lead score price adjustment per point | C4: C - factor
A5: Avg retention probability
A6: Max retention probability cap
A7: Model version
A8: Prepared date
A10: Core Public Price Grid / Guardrails
A11: Key | B11: Programme | C11: Format | D11: Base Price (HK$/hr) | E11: Min Price | F11: Max Price
A12: IGCSE|Group | B12: IGCSE | C12: Group | D12: 480 | E12: =D12*0.9 -> 432 | G12: 可以再detail啲 (Grade 7, 8, 9 with different price)
A13: IGCSE |2:1 | B13: IGCSE | C13: 2:1 | D13: 680 | E13: =D13*0.9 -> 612
A14: IGCSE |1:1 | B14: IGCSE | C14: 1:1 | D14: 980 | E14: =D14*0.9 -> 882
A15: IAL|Group | B15: IAL | C15: Group | D15: 580 | E15: =D15*0.9 -> 522
A16: IAL|2:1 | B16: IAL | C16: 2:1 | D16: 780 | E16: =D16*0.9 -> 702
A17: IAL|1:1 | B17: IAL | C17: 1:1 | D17: 1080 | E17: =D17*0.9 -> 972
A18: IBDP|Group | B18: IBDP | C18: Group | D18: 580 | E18: =D18*0.9 -> 522
A19: IBDP|2:1 | B19: IBDP | C19: 2:1 | D19: 780 | E19: =D19*0.9 -> 702
A20: IBDP|1:1 | B20: IBDP | C20: 1:1 | D20: 1080 | E20: =D20*0.9 -> 972
A21: F1 | B21: HKDSE | C21: 1 | D21: 420 | E21: =D21*0.9 -> 378
A22: F1 | B22: HKDSE | C22: 2 | D22: 336 | E22: =D22*0.9 -> 302.4
A23: F1 | B23: HKDSE | C23: 3 | D23: 273 | E23: =D23*0.9 -> 245.7
A24: F1 | B24: HKDSE | C24: 4 | D24: 231 | E24: =D24*0.9 -> 207.9
A25: F1 | B25: HKDSE | C25: 5 | D25: 210 | E25: =D25*0.9 -> 189
A26: F1 | B26: HKDSE | C26: 6 | D26: 189 | E26: =D26*0.9 -> 170.1
A27: F2 | B27: HKDSE | C27: 1 | D27: 430 | E27: =D27*0.9 -> 387
A28: F2 | B28: HKDSE | C28: 2 | D28: 344 | E28: =D28*0.9 -> 309.6
A29: F2 | B29: HKDSE | C29: 3 | D29: 280 | E29: =D29*0.9 -> 252
A30: F2 | B30: HKDSE | C30: 4 | D30: 237 | E30: =D30*0.9 -> 213.3
A31: F2 | B31: HKDSE | C31: 5 | D31: 215 | E31: =D31*0.9 -> 193.5
A32: F2 | B32: HKDSE | C32: 6 | D32: 194 | E32: =D32*0.9 -> 174.6
... A51: F6 | B51: HKDSE | C51: 1 | D51: 520 | E51: =D51*0.9 -> 468
A52: F6 | B52: HKDSE | C52: 2 | D52: 416 | E52: =D52*0.9 -> 374.4 | H52: 可以再detail啲 (such 1600 - 1800, 1800 - 2000)
A53: F6 | B53: HKDSE | C53: 3 | D53: 338 | E53: =D53*0.9 -> 304.2
A54: F6 | B54: HKDSE | C54: 4 | D54: 286 | E54: =D54*0.9 -> 257.4
A55: F6 | B55: HKDSE | C55: 5 | D55: 260 | E55: =D55*0.9 -> 234
A56: F6 | B56: HKDSE | C56: 6 | D56: 234 | E56: =D56*0.9 -> 210.6
A59: Teacher Tier Factor | E59: Time Slot Factor
A60: Teacher Tier | B60: Price Factor | C60: Teacher Cost % | E60: Time Slot | F60: Factor
A61: Core | B61: 1 | C61: 0.45 | E61: Weekday 08:00-10:00 | F61: 0.85
A62: Experienced | B62: 1.2 | C62: 0.5 | E62: Weekday 10:00-12:00 | F62: 0.85
...

Sheet Dashboard
A1: Dashboard — Funnel, Pricing, Expected Revenue
A3: KPI | B3: Value | C3: Notes / Target
A4: Total leads | B4: =COUNTA(#REF!) -> 1 | C4: All logged leads
A5: Parent replied or later | B5: =COUNTIFS(#REF!,"<>",#REF!,"<>No reply")-COUNTIF(#REF!,"Lost") -> #REF! | C5: Higher is better
A6: Trial booked or later | B6: =COUNTIF(#REF!,"Trial booked")+COUNTIF(#REF!,"Trial attended")+COUNTIF(#REF!,"Enrolled") -> #REF! | C6: Funnel stage
A7: Trial attended or later | B7: =COUNTIF(#REF!,"Trial attended")+COUNTIF(#REF!,"Enrolled") -> #REF! | C7: Funnel stage
A8: Enrolled | B8: =COUNTIF(#REF!,"Enrolled") -> #REF! | C8: Observed outcome
A9: Lost | B9: =COUNTIF(#REF!,"Lost") -> #REF! | C9: Track lost reason
A10: Observed lead→enrol conversion | B10: =IF(B4=0,"",B8/B4) -> #REF! | C10: Target will be set after baseline
A11: Average recommended price | B11: =AVERAGEIF(#REF!,">0",#REF!) -> #REF! | C11: HK$/hr
A12: Total expected revenue | B12: =SUM(#REF!) -> #REF! | C12: Probability-weighted
A13: Total expected gross profit | B13: =SUM(#REF!) -> #REF! | C13: Revenue less teacher cost assumption
A14: Brand / organic lead share | B14: =IF(B4=0,"",COUNTIF(#REF!,"Brand / Organic")/B4) -> #REF! | C14: Vol.4 target: 35% by 90 days, 65% by 12 months
A16: Source | B16: Leads | C16: Expected Revenue | D16: Enrolled | E16: Avg Recommended Price | G16: Programme | H16: Leads | I16: Expected Revenue | J16: Enrolled | K16: Avg Recommended Price
A17: Paid Meta | B17: =COUNTIF(#REF!,A17) -> #REF! | C17: =SUMIF(#REF!,A17,#REF!) -> #REF! | D17: =COUNTIFS(#REF!,A17,#REF!,"Enrolled") -> #REF! | E17: =IFERROR(AVERAGEIFS(#REF!,#REF!,A17,#REF!,">0"),"") | G17: IGCSE/IAL | H17: =COUNTIF(#REF!,G17) -> #REF! | I17: =SUMIF(#REF!,G17,#REF!) -> #REF! | J17: =COUNTIFS(#REF!,G17,#REF!,"Enrolled") -> #REF! | K17: =IFERROR(AVERAGEIFS(#REF!,#REF!,G17,#REF!,">0"),"")
A18: Instagram Organic | B18: =COUNTIF(#REF!,A18) -> #REF! | C18: =SUMIF(#REF!,A18,#REF!) -> #REF! | D18: =COUNTIFS(#REF!,A18,#REF!,"Enrolled") -> #REF! | E18: =IFERROR(AVERAGEIFS(#REF!,#REF!,#REF!,#REF!,">0"),"") | G18: IBDP | H18: =COUNTIF(#REF!,G18) -> #REF! | I18: =SUMIF(#REF!,G18,#REF!) -> #REF! | J18: =COUNTIFS(#REF!,G18,#REF!,"Enrolled") -> #REF! | K18: =IFERROR(AVERAGEIFS(#REF!,#REF!,G18,#REF!,">0"),"")
A19: Referral | B19: =COUNTIF(#REF!,A19) -> #REF! | C19: =SUMIF(#REF!,A19,#REF!) -> #REF! | D19: =COUNTIFS(#REF!,A19,#REF!,"Enrolled") -> #REF! | E19: =IFERROR(AVERAGEIFS(#REF!,#REF!,A18,#REF!,">0"),"") | G19: TOK/EE | H19: =COUNTIF(#REF!,G19) -> #REF! | I19: =SUMIF(#REF!,G19,#REF!) -> #REF! | J19: =COUNTIFS(#REF!,G19,#REF!,"Enrolled") -> #REF! | K19: =IFERROR(AVERAGEIFS(#REF!,#REF!,G19,#REF!,">0"),"")
A20: Google Search | B20: =COUNTIF(#REF!,A20) -> #REF! | C20: =SUMIF(#REF!,A20,#REF!) -> #REF! | D20: =COUNTIFS(#REF!,A20,#REF!,"Enrolled") -> #REF! | E20: =IFERROR(AVERAGEIFS(#REF!,#REF!,A19,#REF!,">0"),"")
A21: Other | B21: =COUNTIF(#REF!,A21) -> #REF! | C21: =SUMIF(#REF!,A21,#REF!) -> #REF! | D21: =COUNTIFS(#REF!,A21,#REF!,"Enrolled") -> #REF! | E21: =IFERROR(AVERAGEIFS(#REF!,#REF!,A20,#REF!,">0"),"")
E22: =IFERROR(AVERAGEIFS(#REF!,#REF!,#REF!,#REF!,">0"),"")
E23: =IFERROR(AVERAGEIFS(#REF!,#REF!,A23,#REF!,">0"),"")
E24: =IFERROR(AVERAGEIFS(#REF!,#REF!,A21,#REF!,">0"),"")

Sheet Scenario_Simulator
A1: Scenario Simulator — One-Case Price Recommendation
A3: Input | B3: Value | C3: Notes | E3: Output | F3: Formula Result | G3: Interpretation | H3: Calculation Link
A4: Programme | B4: IBDP | C4: Dropdown | E4: Capacity Utilisation | F4: =IFERROR(B14/B15,"") -> 0.75 | G4: Class/tutor load
A5: Subject Type | B5: IBDP HL | C5: Dropdown | E5: Base Price | F5: =SUMIFS(Assumptions!$D$12:$D$57,Assumptions!$B$12:$B$57,B4,Assumptions!$C$12:$C$57,B6) -> 1080 | G5: Public price anchor | H5: Assumptions price grid
A6: Format | B6: 1:1 | C6: Dropdown | E6: Min Price | F6: =SUMIFS(Assumptions!$E$12:$E$57,Assumptions!$B$12:$B$57,B4,Assumptions!$C$12:$C$57,B6) -> 972 | G6: Guardrail | H6: Assumptions price grid
A7: Teacher Tier | B7: Senior | C7: Dropdown | E7: Max Price | F7: =SUMIFS(Assumptions!$F$12:$F$57,Assumptions!$B$12:$B$57,B4,Assumptions!$C$12:$C$57,B6) -> 0 | G7: Guardrail | H7: Assumptions price grid
A8: Time Slot | B8: Weekend | C8: Dropdown | E8: Teacher Factor | F8: =IFERROR(SUMIF(Assumptions!$A$61:$A$64,B7,Assumptions!$B$61:$B$64),1) -> 1.3 | G8: Tier premium | H8: Assumptions teacher factor
A9: Source | B9: Referral | C9: Dropdown | E9: Time Factor | F9: =IFERROR(SUMIF(Assumptions!$E$61:$E$78,B8,Assumptions!$F$61:$F$78),1) -> 0 | G9: Peak/non-peak | H9: Assumptions time factor
A10: Price Sensitivity | B10: Medium | C10: Dropdown | E10: Capacity Factor | F10: =IFERROR(LOOKUP(F4,Assumptions!$A$83:$A$87,Assumptions!$C$83:$C$87),1) -> 1 | G10: Scarcity/underfilled adjustment | H10: Assumptions capacity factor
A11: Urgency | B11: High | C11: Dropdown | E11: Subject Factor | F11: =IFERROR(SUMIF(Assumptions!$E$82:$E$94,B5,Assumptions!$F$82:$F$94),1) -> 1 | G11: Demand adjustment | H11: Assumptions subject factor
A12: Parent Status | B12: Replied | C12: Dropdown | E12: Lead Score | F12: =IFERROR(SUMIF(Assumptions!#REF!,B9,Assumptions!#REF!),0)+IFERROR(SUMIF(Assumptions!$A$98:$A$100,B10,Assumptions!$B$98:$B$100),0)+IFERROR(SUMIF(Assumptions!$D$98:$D$100,B11,Assumptions!$E$98:$E$100),0)+IFERROR(SUMIF(Assumptions!$A$104:$A$109,B12,Assumptions!$B$104:$B$109),0)+IFERROR(SUMIF(Assumptions!$D$104:$D$107,B13,Assumptions!$E$104:$E$107),0) -> 2 | G12: Higher score allows premium confidence | H12: Scoring tables
A13: Trial Outcome | B13: Not yet | C13: Dropdown | E13: Recommended Price | F13: =IF(B17<>"",B17,IF(F5=0,"",ROUND(MAX(F6,MIN(F7,F5*F8*F9*F10*F11*(1+F12*Assumptions!$B$4)))/10,0)*10)) -> 970 | G13: Recommended HK$/hr | H13: Capped pricing formula
A14: Current Students | B14: 6 | C14: Current class / tutor load | E14: Recommended Offer | F14: =IF(AND(B10="High",F4<0.7),"Paid trial + deduct on enrolment",IF(AND(B11="High",F4>=0.7),"Senior/intensive package; no hourly discount",IF(B9="Referral","Academic Mentor + standard package",IF(F4<0.4,"Non-peak/group starter package","Standard package + mentor review")))) -> Senior/intensive package; no hourly discount | G14: What staff should message | H14: Offer decision tree
A15: Max Capacity | B15: 8 | C15: Seats / capacity | E15: P Lead→Enrol | F15: =IF(B12="Enrolled",1,IF(B12="Lost",0,IF(B12="Trial attended",F26,IF(B12="Trial booked",F25*F26,IF(B12="Replied",F24*F25*F26,F23*F24*F25*F26))))) -> 0 | G15: Stage-adjusted probability | H15: Source probabilities
A16: Expected Hours Override | C16: Optional | E16: P 8-Lesson Retention | F16: =MAX(0,MIN(Assumptions!$B$6,IFERROR(SUMIF(Assumptions!#REF!,B9,Assumptions!#REF!),0.75)+IF(B13="Strong",0.05,IF(B13="Weak",-0.1,0))+IF(B10="High",-0.05,0)+IF(B9="Referral",0.03,0))) -> 0.78 | G16: Retention confidence | H16: Source + trial outcome
A17: Price Override | C17: Optional manual quote | E17: Expected Billable Hours | F17: =IF(B16<>"",B16,SUMIFS(Assumptions!$G$12:$G$50,Assumptions!$B$12:$B$57,B4,Assumptions!$C$12:$C$57,B6)) -> #VALUE! | G17: Hours/lessons assumed | H17: Assumptions price grid
E18: Expected Revenue | F18: =F13*F15*F16*F17 -> #VALUE! | G18: Price × probability × retention × hours | H18: Expected revenue formula
E19: Teacher Cost % | F19: =IFERROR(SUMIF(Assumptions!$A$61:$A$64,B7,Assumptions!$C$61:$C$64),0.5) -> 0.55 | G19: Gross margin assumption | H19: Teacher tier
E20: Expected Gross Profit | F20: =F18*(1-F19) -> #VALUE! | G20: Revenue less teacher cost | H20: Gross profit formula
E22: Probability Helper | F22: Value | G22: Meaning | H22: Source
E23: P Parent Reply | F23: =IFERROR(SUMIF(Assumptions!#REF!,B9,Assumptions!#REF!),0) -> 0 | G23: Default from selected source | H23: Assumptions source table
E24: P Trial Book | F24: =IFERROR(SUMIF(Assumptions!#REF!,B9,Assumptions!#REF!),0) -> 0 | G24: Default from selected source | H24: Assumptions source table
E25: P Trial Attend | F25: =IFERROR(SUMIF(Assumptions!#REF!,B9,Assumptions!#REF!),0) -> 0 | G25: Default from selected source | H25: Assumptions source table
E26: P Enrol After Trial | F26: =IFERROR(SUMIF(Assumptions!#REF!,B9,Assumptions!#REF!),0) -> 0 | G26: Default from selected source | H26: Assumptions source table
